Traceback (most recent call last):

  File "/home/owen/progs/firedrake-complex/firedrake/src/PyOP2/pyop2/caching.py", line 197, in __new__

    return cls._cache_lookup(key)

  File "/home/owen/progs/firedrake-complex/firedrake/src/PyOP2/pyop2/caching.py", line 205, in _cache_lookup

    return cls._cache[key]

KeyError: ('2687a2ab231221e26912a46dbf073d18', False, False, False, <class 'pyop2.sequential.Arg'>, (1,), dtype('complex128'), 1, (<class 'pyop2.base.IterationIndex'>, 0), None, Access('INC'), <class 'pyop2.sequential.Arg'>, (2,), dtype('complex128'), 3, (<class 'pyop2.base.IterationIndex'>, 0), None, Access('READ'), <class 'pyop2.sequential.Arg'>, (1,), dtype('complex128'), 1, (<class 'pyop2.base.IterationIndex'>, 0), None, Access('READ'))

During handling of the above exception, another exception occurred:

Traceback (most recent call last):

  File "/home/owen/progs/firedrake-complex/firedrake/src/PyOP2/pyop2/compilation.py", line 245, in get_so

    return ctypes.CDLL(soname)

  File "/usr/lib/python3.5/ctypes/__init__.py", line 347, in __init__

    self._handle = _dlopen(self._name, mode)

OSError: /home/owen/progs/firedrake-complex/firedrake/.cache/pyop2/625ebc7a6a95e01f63eb28fe45fc01c3.so: cannot open shared object file: No such file or directory

During handling of the above exception, another exception occurred:

Traceback (most recent call last):

  File "/home/owen/progs/firedrake-complex/firedrake/src/PyOP2/pyop2/compilation.py", line 276, in get_so

    stdout=log)

  File "/usr/lib/python3.5/subprocess.py", line 581, in check_call

    raise CalledProcessError(retcode, cmd)

subprocess.CalledProcessError: Command '['mpicc', '-std=c99', '-fPIC', '-Wall', '-march=native', '-O3', '-ffast-math', '-I/home/owen/progs/firedrake-complex/firedrake/lib/python3.5/site-packages/petsc/include', '-I/home/owen/progs/firedrake-complex/firedrake/src/PyOP2/pyop2', '-msse', '-o', '/home/owen/progs/firedrake-complex/firedrake/.cache/pyop2/625ebc7a6a95e01f63eb28fe45fc01c3_p31518.so.tmp', '/home/owen/progs/firedrake-complex/firedrake/.cache/pyop2/625ebc7a6a95e01f63eb28fe45fc01c3_p31518.c', '-shared', '-L/home/owen/progs/firedrake-complex/firedrake/lib/python3.5/site-packages/petsc/lib', '-Wl,-rpath,/home/owen/progs/firedrake-complex/firedrake/lib/python3.5/site-packages/petsc/lib', '-lpetsc', '-lm']' returned non-zero exit status 1

During handling of the above exception, another exception occurred:

Traceback (most recent call last):

  File "/usr/lib/python3.5/contextlib.py", line 59, in __enter__

    return next(self.gen)

  File "/home/owen/progs/firedrake-complex/firedrake/src/PyOP2/pyop2/petsc_base.py", line 331, in vec_context

    write=access is not base.READ)

  File "/home/owen/progs/firedrake-complex/firedrake/src/PyOP2/pyop2/base.py", line 1460, in _force_evaluation

    _trace.evaluate(reads, writes)

  File "/home/owen/progs/firedrake-complex/firedrake/src/PyOP2/pyop2/base.py", line 193, in evaluate

    comp._run()

  File "/home/owen/progs/firedrake-complex/firedrake/src/PyOP2/pyop2/base.py", line 3971, in _run

    return self.compute()

  File "/home/owen/progs/firedrake-complex/firedrake/src/PyOP2/pyop2/base.py", line 4012, in compute

    fun = self._jitmodule

  File "/home/owen/progs/firedrake-complex/firedrake/src/PyOP2/pyop2/utils.py", line 62, in __get__

    obj.__dict__[self.__name__] = result = self.fget(obj)

  File "/home/owen/progs/firedrake-complex/firedrake/src/PyOP2/pyop2/sequential.py", line 927, in _jitmodule

    pass_layer_arg=self._pass_layer_arg)

  File "/home/owen/progs/firedrake-complex/firedrake/src/PyOP2/pyop2/caching.py", line 199, in __new__

    obj = make_obj()

  File "/home/owen/progs/firedrake-complex/firedrake/src/PyOP2/pyop2/caching.py", line 189, in make_obj

    obj.__init__(*args, **kwargs)

  File "/home/owen/progs/firedrake-complex/firedrake/src/PyOP2/pyop2/sequential.py", line 756, in __init__

    self.compile()

  File "/home/owen/progs/firedrake-complex/firedrake/src/PyOP2/pyop2/sequential.py", line 842, in compile

    comm=self.comm)

  File "/home/owen/progs/firedrake-complex/firedrake/src/PyOP2/pyop2/compilation.py", line 440, in load

    dll = compiler.get_so(src, extension)

  File "/home/owen/progs/firedrake-complex/firedrake/src/PyOP2/pyop2/compilation.py", line 321, in get_so

    os.rename(tmpname, soname)

  File "/usr/lib/python3.5/contextlib.py", line 77, in __exit__

    self.gen.throw(type, value, traceback)

  File "/home/owen/progs/firedrake-complex/firedrake/src/PyOP2/pyop2/logger.py", line 90, in progress

    yield

  File "/home/owen/progs/firedrake-complex/firedrake/src/PyOP2/pyop2/compilation.py", line 282, in get_so

    Compile errors in %s""" % (e.cmd, e.returncode, logfile, errfile))

pyop2.exceptions.CompilationError: Command "['mpicc', '-std=c99', '-fPIC', '-Wall', '-march=native', '-O3', '-ffast-math', '-I/home/owen/progs/firedrake-complex/firedrake/lib/python3.5/site-packages/petsc/include', '-I/home/owen/progs/firedrake-complex/firedrake/src/PyOP2/pyop2', '-msse', '-o', '/home/owen/progs/firedrake-complex/firedrake/.cache/pyop2/625ebc7a6a95e01f63eb28fe45fc01c3_p31518.so.tmp', '/home/owen/progs/firedrake-complex/firedrake/.cache/pyop2/625ebc7a6a95e01f63eb28fe45fc01c3_p31518.c', '-shared', '-L/home/owen/progs/firedrake-complex/firedrake/lib/python3.5/site-packages/petsc/lib', '-Wl,-rpath,/home/owen/progs/firedrake-complex/firedrake/lib/python3.5/site-packages/petsc/lib', '-lpetsc', '-lm']" return error status 1.

Unable to compile code

Compile log in /home/owen/progs/firedrake-complex/firedrake/.cache/pyop2/625ebc7a6a95e01f63eb28fe45fc01c3_p31518.log

Compile errors in /home/owen/progs/firedrake-complex/firedrake/.cache/pyop2/625ebc7a6a95e01f63eb28fe45fc01c3_p31518.err

During handling of the above exception, another exception occurred:

SystemError: <built-in method insert of list object at 0x7f56d4731c08> returned a result with an error set

Exception ignored in: 'petsc4py.PETSc.traceback'

SystemError: <built-in method insert of list object at 0x7f56d4731c08> returned a result with an error set